Workbook

Sheet Data
A1: =IFERROR(__xludf.DUMMYFUNCTION("IMPORTRANGE(""https://docs.google.com/spreadsheets/d/1DL0yY55duy_4Vb7h9L0y6XEA3qVJwBjNzmRrPMQrc5E/edit?gid=0#gid=0"",""All Item List!A1:O"")"),"") | B1: =IFERROR(__xludf.DUMMYFUNCTION("""COMPUTED_VALUE"""),"Total Items Count :") -> Total Items Count : | D1: =IFERROR(__xludf.DUMMYFUNCTION("""COMPUTED_VALUE"""),301.0) -> 301
B2: =IFERROR(__xludf.DUMMYFUNCTION("""COMPUTED_VALUE"""),"Details Confirmed :") -> Details Confirmed : | D2: =IFERROR(__xludf.DUMMYFUNCTION("""COMPUTED_VALUE"""),246.0) -> 246
A3: =IFERROR(__xludf.DUMMYFUNCTION("""COMPUTED_VALUE"""),"Details Confirm") -> Details Confirm | B3: =IFERROR(__xludf.DUMMYFUNCTION("""COMPUTED_VALUE"""),"Image") -> Image | C3: =IFERROR(__xludf.DUMMYFUNCTION("""COMPUTED_VALUE"""),"Item ID") -> Item ID | D3: =IFERROR(__xludf.DUMMYFUNCTION("""COMPUTED_VALUE"""),"Image URL") -> Image URL | E3: =IFERROR(__xludf.DUMMYFUNCTION("""COMPUTED_VALUE"""),"Item EN") -> Item EN | F3: =IFERROR(__xludf.DUMMYFUNCTION("""COMPUTED_VALUE"""),"Price") -> Price | G3: =IFERROR(__xludf.DUMMYFUNCTION("""COMPUTED_VALUE"""),"GC Price") -> GC Price | H3: =IFERROR(__xludf.DUMMYFUNCTION("""COMPUTED_VALUE"""),"Dollar Price") -> Dollar Price | I3: =IFERROR(__xludf.DUMMYFUNCTION("""COMPUTED_VALUE"""),"Item Type") -> Item Type | J3: =IFERROR(__xludf.DUMMYFUNCTION("""COMPUTED_VALUE"""),"Stackable") -> Stackable | K3: =IFERROR(__xludf.DUMMYFUNCTION("""COMPUTED_VALUE"""),"Tier") -> Tier | L3: =IFERROR(__xludf.DUMMYFUNCTION("""COMPUTED_VALUE"""),"SFTP Url") -> SFTP Url | N3: =IFERROR(__xludf.DUMMYFUNCTION("""COMPUTED_VALUE"""),"Description") -> Description | O3: =IFERROR(__xludf.DUMMYFUNCTION("""COMPUTED_VALUE"""),"Aztek Item ID") -> Aztek Item ID
A4: =IFERROR(__xludf.DUMMYFUNCTION("""COMPUTED_VALUE"""),TRUE) -> TRUE | B4: =IFERROR(__xludf.DUMMYFUNCTION("""COMPUTED_VALUE"""),"") | C4: =IFERROR(__xludf.DUMMYFUNCTION("""COMPUTED_VALUE"""),400136.0) -> 400136 | D4: =IFERROR(__xludf.DUMMYFUNCTION("""COMPUTED_VALUE"""),"https://cdn.exe.in.th/marketing/WarzTH_LE/Item%20Dict/12g_slug.png") -> https://cdn.exe.in.th/marketing/WarzTH_LE/Item%20Dict/12g_slug.png | E4: =IFERROR(__xludf.DUMMYFUNCTION("""COMPUTED_VALUE"""),"12 Gauge Slug") -> 12 Gauge Slug | F4: =IFERROR(__xludf.DUMMYFUNCTION("""COMPUTED_VALUE"""),1.5) -> 1.5 | G4: =IFERROR(__xludf.DUMMYFUNCTION("""COMPUTED_VALUE"""),"-") -> - | H4: =IFERROR(__xludf.DUMMYFUNCTION("""COMPUTED_VALUE"""),"1,250 Dollars") -> 1,250 Dollars | I4: =IFERROR(__xludf.DUMMYFUNCTION("""COMPUTED_VALUE"""),"Ammo") -> Ammo | J4: =IFERROR(__xludf.DUMMYFUNCTION("""COMPUTED_VALUE"""),"Yes") -> Yes | L4: =IFERROR(__xludf.DUMMYFUNCTION("""COMPUTED_VALUE"""),"sftp://graphic@103.41.58.141/marketing/WarzTH_LE/Item%20Dict/12g_slug.png") -> sftp://graphic@103.41.58.141/marketing/WarzTH_LE/Item%20Dict/12g_slug.png | N4: =IFERROR(__xludf.DUMMYFUNCTION("""COMPUTED_VALUE"""),"8 slugs for use in the Mossberg and KT Decider shotguns") -> 8 slugs for use in the Mossberg and KT Decider shotguns
A5: =IFERROR(__xludf.DUMMYFUNCTION("""COMPUTED_VALUE"""),TRUE) -> TRUE | B5: =IFERROR(__xludf.DUMMYFUNCTION("""COMPUTED_VALUE"""),"") | C5: =IFERROR(__xludf.DUMMYFUNCTION("""COMPUTED_VALUE"""),400144.0) -> 400144 | D5: =IFERROR(__xludf.DUMMYFUNCTION("""COMPUTED_VALUE"""),"https://cdn.exe.in.th/marketing/WarzTH_LE/Item%20Dict/ruger_mag.png") -> https://cdn.exe.in.th/marketing/WarzTH_LE/Item%20Dict/ruger_mag.png | E5: =IFERROR(__xludf.DUMMYFUNCTION("""COMPUTED_VALUE"""),".22 Caliber clip") -> .22 Caliber clip | F5: =IFERROR(__xludf.DUMMYFUNCTION("""COMPUTED_VALUE"""),0.8) -> 0.8 | G5: =IFERROR(__xludf.DUMMYFUNCTION("""COMPUTED_VALUE"""),"-") -> - | H5: =IFERROR(__xludf.DUMMYFUNCTION("""COMPUTED_VALUE"""),"700 Dollars") -> 700 Dollars | I5: =IFERROR(__xludf.DUMMYFUNCTION("""COMPUTED_VALUE"""),"Ammo") -> Ammo | J5: =IFERROR(__xludf.DUMMYFUNCTION("""COMPUTED_VALUE"""),"Yes") -> Yes | L5: =IFERROR(__xludf.DUMMYFUNCTION("""COMPUTED_VALUE"""),"sftp://graphic@103.41.58.141/marketing/WarzTH_LE/Item%20Dict/ruger_mag.png") -> sftp://graphic@103.41.58.141/marketing/WarzTH_LE/Item%20Dict/ruger_mag.png | N5: =IFERROR(__xludf.DUMMYFUNCTION("""COMPUTED_VALUE"""),"10 round, 22 cal ammo clip for Ruger pistols and rifles") -> 10 round, 22 cal ammo clip for Ruger pistols and rifles
A6: =IFERROR(__xludf.DUMMYFUNCTION("""COMPUTED_VALUE"""),TRUE) -> TRUE | B6: =IFERROR(__xludf.DUMMYFUNCTION("""COMPUTED_VALUE"""),"") | C6: =IFERROR(__xludf.DUMMYFUNCTION("""COMPUTED_VALUE"""),400137.0) -> 400137 | D6: =IFERROR(__xludf.DUMMYFUNCTION("""COMPUTED_VALUE"""),"https://cdn.exe.in.th/marketing/WarzTH_LE/Item%20Dict/12g.png") -> https://cdn.exe.in.th/marketing/WarzTH_LE/Item%20Dict/12g.png | E6: =IFERROR(__xludf.DUMMYFUNCTION("""COMPUTED_VALUE"""),"2x 12gauge") -> 2x 12gauge | F6: =IFERROR(__xludf.DUMMYFUNCTION("""COMPUTED_VALUE"""),1.5) -> 1.5 | G6: =IFERROR(__xludf.DUMMYFUNCTION("""COMPUTED_VALUE"""),"-") -> - | H6: =IFERROR(__xludf.DUMMYFUNCTION("""COMPUTED_VALUE"""),"1,250 Dollars") -> 1,250 Dollars | I6: =IFERROR(__xludf.DUMMYFUNCTION("""COMPUTED_VALUE"""),"Ammo") -> Ammo | J6: =IFERROR(__xludf.DUMMYFUNCTION("""COMPUTED_VALUE"""),"Yes") -> Yes | L6: =IFERROR(__xludf.DUMMYFUNCTION("""COMPUTED_VALUE"""),"sftp://graphic@103.41.58.141/marketing/WarzTH_LE/Item%20Dict/12g.png") -> sftp://graphic@103.41.58.141/marketing/WarzTH_LE/Item%20Dict/12g.png | N6: =IFERROR(__xludf.DUMMYFUNCTION("""COMPUTED_VALUE"""),"Ammo for use with the double barrel shotgun") -> Ammo for use with the double barrel shotgun
A7: =IFERROR(__xludf.DUMMYFUNCTION("""COMPUTED_VALUE"""),TRUE) -> TRUE | B7: =IFERROR(__xludf.DUMMYFUNCTION("""COMPUTED_VALUE"""),"") | C7: =IFERROR(__xludf.DUMMYFUNCTION("""COMPUTED_VALUE"""),400070.0) -> 400070 | D7: =IFERROR(__xludf.DUMMYFUNCTION("""COMPUTED_VALUE"""),"https://cdn.exe.in.th/marketing/WarzTH_LE/Item%20Dict/.308_ammo.png") -> https://cdn.exe.in.th/marketing/WarzTH_LE/Item%20Dict/.308_ammo.png | E7: =IFERROR(__xludf.DUMMYFUNCTION("""COMPUTED_VALUE"""),".308 Winchester Sniper rifle ammo") -> .308 Winchester Sniper rifle ammo | F7: =IFERROR(__xludf.DUMMYFUNCTION("""COMPUTED_VALUE"""),3.0) -> 3 | G7: =IFERROR(__xludf.DUMMYFUNCTION("""COMPUTED_VALUE"""),"30 GC") -> 30 GC | H7: =IFERROR(__xludf.DUMMYFUNCTION("""COMPUTED_VALUE"""),"-") -> - | I7: =IFERROR(__xludf.DUMMYFUNCTION("""COMPUTED_VALUE"""),"Ammo") -> Ammo | J7: =IFERROR(__xludf.DUMMYFUNCTION("""COMPUTED_VALUE"""),"Yes") -> Yes | L7: =IFERROR(__xludf.DUMMYFUNCTION("""COMPUTED_VALUE"""),"sftp://graphic@103.41.58.141/marketing/WarzTH_LE/Item%20Dict/.308_ammo.png") -> sftp://graphic@103.41.58.141/marketing/WarzTH_LE/Item%20Dict/.308_ammo.png | N7: =IFERROR(__xludf.DUMMYFUNCTION("""COMPUTED_VALUE"""),"7.62x51mm NATO sniper rifle clip for use with the .308 Winchester Sniple Rifle. Magazine holds 10 rounds") -> 7.62x51mm NATO sniper rifle clip for use with the .308 Winchester Sniple Rifle. Magazine holds 10 rounds
A8: =IFERROR(__xludf.DUMMYFUNCTION("""COMPUTED_VALUE"""),TRUE) -> TRUE | B8: =IFERROR(__xludf.DUMMYFUNCTION("""COMPUTED_VALUE"""),"") | C8: =IFERROR(__xludf.DUMMYFUNCTION("""COMPUTED_VALUE"""),400154.0) -> 400154 | D8: =IFERROR(__xludf.DUMMYFUNCTION("""COMPUTED_VALUE"""),"https://cdn.exe.in.th/marketing/WarzTH_LE/Item%20Dict/.40_1911_mag.png") -> https://cdn.exe.in.th/marketing/WarzTH_LE/Item%20Dict/.40_1911_mag.png | E8: =IFERROR(__xludf.DUMMYFUNCTION("""COMPUTED_VALUE"""),".40 caliber 1911 Mag") -> .40 caliber 1911 Mag | F8: =IFERROR(__xludf.DUMMYFUNCTION("""COMPUTED_VALUE"""),0.6) -> 0.6 | G8: =IFERROR(__xludf.DUMMYFUNCTION("""COMPUTED_VALUE"""),"-") -> - | H8: =IFERROR(__xludf.DUMMYFUNCTION("""COMPUTED_VALUE"""),"500 Dollars") -> 500 Dollars | I8: =IFERROR(__xludf.DUMMYFUNCTION("""COMPUTED_VALUE"""),"Ammo") -> Ammo | J8: =IFERROR(__xludf.DUMMYFUNCTION("""COMPUTED_VALUE"""),"Yes") -> Yes | L8: =IFERROR(__xludf.DUMMYFUNCTION("""COMPUTED_VALUE"""),"sftp://graphic@103.41.58.141/marketing/WarzTH_LE/Item%20Dict/.40_1911_mag.png") -> sftp://graphic@103.41.58.141/marketing/WarzTH_LE/Item%20Dict/.40_1911_mag.png | N8: =IFERROR(__xludf.DUMMYFUNCTION("""COMPUTED_VALUE"""),"7 round single-stack magazine for the 1911") -> 7 round single-stack magazine for the 1911
A9: =IFERROR(__xludf.DUMMYFUNCTION("""COMPUTED_VALUE"""),TRUE) -> TRUE | B9: =IFERROR(__xludf.DUMMYFUNCTION("""COMPUTED_VALUE"""),"") | C9: =IFERROR(__xludf.DUMMYFUNCTION("""COMPUTED_VALUE"""),400135.0) -> 400135 | D9: =IFERROR(__xludf.DUMMYFUNCTION("""COMPUTED_VALUE"""),"https://cdn.exe.in.th/marketing/WarzTH_LE/Item%20Dict/.45ee_ammo.png") -> https://cdn.exe.in.th/marketing/WarzTH_LE/Item%20Dict/.45ee_ammo.png | E9: =IFERROR(__xludf.DUMMYFUNCTION("""COMPUTED_VALUE"""),".45 ACP STI Eagle Elite ammo") -> .45 ACP STI Eagle Elite ammo | F9: =IFERROR(__xludf.DUMMYFUNCTION("""COMPUTED_VALUE"""),1.5) -> 1.5 | G9: =IFERROR(__xludf.DUMMYFUNCTION("""COMPUTED_VALUE"""),"-") -> - | H9: =IFERROR(__xludf.DUMMYFUNCTION("""COMPUTED_VALUE"""),"1,250 Dollars") -> 1,250 Dollars | I9: =IFERROR(__xludf.DUMMYFUNCTION("""COMPUTED_VALUE"""),"Ammo") -> Ammo | J9: =IFERROR(__xludf.DUMMYFUNCTION("""COMPUTED_VALUE"""),"Yes") -> Yes | L9: =IFERROR(__xludf.DUMMYFUNCTION("""COMPUTED_VALUE"""),"sftp://graphic@103.41.58.141/marketing/WarzTH_LE/Item%20Dict/.45ee_ammo.png") -> sftp://graphic@103.41.58.141/marketing/WarzTH_LE/Item%20Dict/.45ee_ammo.png | N9: =IFERROR(__xludf.DUMMYFUNCTION("""COMPUTED_VALUE"""),".45 ACP 10 rounds magazine for the STI Eagle Elite handgun") -> .45 ACP 10 rounds magazine for the STI Eagle Elite handgun
A10: =IFERROR(__xludf.DUMMYFUNCTION("""COMPUTED_VALUE"""),TRUE) -> TRUE | B10: =IFERROR(__xludf.DUMMYFUNCTION("""COMPUTED_VALUE"""),"") | C10: =IFERROR(__xludf.DUMMYFUNCTION("""COMPUTED_VALUE"""),400133.0) -> 400133 | D10: =IFERROR(__xludf.DUMMYFUNCTION("""COMPUTED_VALUE"""),"https://cdn.exe.in.th/marketing/WarzTH_LE/Item%20Dict/.50_ammo.png") -> https://cdn.exe.in.th/marketing/WarzTH_LE/Item%20Dict/.50_ammo.png | E10: =IFERROR(__xludf.DUMMYFUNCTION("""COMPUTED_VALUE"""),".50 BMG") -> .50 BMG | F10: =IFERROR(__xludf.DUMMYFUNCTION("""COMPUTED_VALUE"""),5.0) -> 5 | G10: =IFERROR(__xludf.DUMMYFUNCTION("""COMPUTED_VALUE"""),"50 GC") -> 50 GC | H10: =IFERROR(__xludf.DUMMYFUNCTION("""COMPUTED_VALUE"""),"-") -> - | I10: =IFERROR(__xludf.DUMMYFUNCTION("""COMPUTED_VALUE"""),"Ammo") -> Ammo | J10: =IFERROR(__xludf.DUMMYFUNCTION("""COMPUTED_VALUE"""),"Yes") -> Yes | L10: =IFERROR(__xludf.DUMMYFUNCTION("""COMPUTED_VALUE"""),"sftp://graphic@103.41.58.141/marketing/WarzTH_LE/Item%20Dict/.50_ammo.png") -> sftp://graphic@103.41.58.141/marketing/WarzTH_LE/Item%20Dict/.50_ammo.png | N10: =IFERROR(__xludf.DUMMYFUNCTION("""COMPUTED_VALUE"""),"12.7x99mm NATO anti material rounds for M107A1 rifle. 5 rounds per magazine") -> 12.7x99mm NATO anti material rounds for M107A1 rifle. 5 rounds per magazine
A11: =IFERROR(__xludf.DUMMYFUNCTION("""COMPUTED_VALUE"""),TRUE) -> TRUE | B11: =IFERROR(__xludf.DUMMYFUNCTION("""COMPUTED_VALUE"""),"") | C11: =IFERROR(__xludf.DUMMYFUNCTION("""COMPUTED_VALUE"""),400001.0) -> 400001 | D11: =IFERROR(__xludf.DUMMYFUNCTION("""COMPUTED_VALUE"""),"https://cdn.exe.in.th/marketing/WarzTH_LE/Item%20Dict/5.45AK_30.png") -> https://cdn.exe.in.th/marketing/WarzTH_LE/Item%20Dict/5.45AK_30.png | E11: =IFERROR(__xludf.DUMMYFUNCTION("""COMPUTED_VALUE"""),"5.45 AK 30") -> 5.45 AK 30 | F11: =IFERROR(__xludf.DUMMYFUNCTION("""COMPUTED_VALUE"""),1.5) -> 1.5 | G11: =IFERROR(__xludf.DUMMYFUNCTION("""COMPUTED_VALUE"""),"-") -> - | H11: =IFERROR(__xludf.DUMMYFUNCTION("""COMPUTED_VALUE"""),"1,200 Dollars") -> 1,200 Dollars | I11: =IFERROR(__xludf.DUMMYFUNCTION("""COMPUTED_VALUE"""),"Ammo") -> Ammo | J11: =IFERROR(__xludf.DUMMYFUNCTION("""COMPUTED_VALUE"""),"Yes") -> Yes | L11: =IFERROR(__xludf.DUMMYFUNCTION("""COMPUTED_VALUE"""),"sftp://graphic@103.41.58.141/marketing/WarzTH_LE/Item%20Dict/5.45AK_30.png") -> sftp://graphic@103.41.58.141/marketing/WarzTH_LE/Item%20Dict/5.45AK_30.png | N11: =IFERROR(__xludf.DUMMYFUNCTION("""COMPUTED_VALUE"""),"This is a standard 5.45x39mm 30 rounds clip for the russian AK 74M family of rifles") -> This is a standard 5.45x39mm 30 rounds clip for the russian AK 74M family of rifles
A12: =IFERROR(__xludf.DUMMYFUNCTION("""COMPUTED_VALUE"""),TRUE) -> TRUE | B12: =IFERROR(__xludf.DUMMYFUNCTION("""COMPUTED_VALUE"""),"") | C12: =IFERROR(__xludf.DUMMYFUNCTION("""COMPUTED_VALUE"""),400069.0) -> 400069 | D12: =IFERROR(__xludf.DUMMYFUNCTION("""COMPUTED_VALUE"""),"https://cdn.exe.in.th/marketing/WarzTH_LE/Item%20Dict/5.45AK_45.png") -> https://cdn.exe.in.th/marketing/WarzTH_LE/Item%20Dict/5.45AK_45.png | E12: =IFERROR(__xludf.DUMMYFUNCTION("""COMPUTED_VALUE"""),"5.45 AK 45") -> 5.45 AK 45 | F12: =IFERROR(__xludf.DUMMYFUNCTION("""COMPUTED_VALUE"""),2.5) -> 2.5 | G12: =IFERROR(__xludf.DUMMYFUNCTION("""COMPUTED_VALUE"""),"-") -> - | H12: =IFERROR(__xludf.DUMMYFUNCTION("""COMPUTED_VALUE"""),"2,000 Dollars") -> 2,000 Dollars | I12: =IFERROR(__xludf.DUMMYFUNCTION("""COMPUTED_VALUE"""),"Ammo") -> Ammo | J12: =IFERROR(__xludf.DUMMYFUNCTION("""COMPUTED_VALUE"""),"Yes") -> Yes | L12: =IFERROR(__xludf.DUMMYFUNCTION("""COMPUTED_VALUE"""),"sftp://graphic@103.41.58.141/marketing/WarzTH_LE/Item%20Dict/5.45AK_45.png") -> sftp://graphic@103.41.58.141/marketing/WarzTH_LE/Item%20Dict/5.45AK_45.png | N12: =IFERROR(__xludf.DUMMYFUNCTION("""COMPUTED_VALUE"""),"This is a standard 5.45x39mm 45 rounds clip for the russian AK74 family of rifles") -> This is a standard 5.45x39mm 45 rounds clip for the russian AK74 family of rifles
A13: =IFERROR(__xludf.DUMMYFUNCTION("""COMPUTED_VALUE"""),TRUE) -> TRUE | B13: =IFERROR(__xludf.DUMMYFUNCTION("""COMPUTED_VALUE"""),"") | C13: =IFERROR(__xludf.DUMMYFUNCTION("""COMPUTED_VALUE"""),400100.0) -> 400100 | D13: =IFERROR(__xludf.DUMMYFUNCTION("""COMPUTED_VALUE"""),"https://cdn.exe.in.th/marketing/WarzTH_LE/Item%20Dict/5.45AK_drum.png") -> https://cdn.exe.in.th/marketing/WarzTH_LE/Item%20Dict/5.45AK_drum.png | E13: =IFERROR(__xludf.DUMMYFUNCTION("""COMPUTED_VALUE"""),"5.45 AK Drum") -> 5.45 AK Drum | F13: =IFERROR(__xludf.DUMMYFUNCTION("""COMPUTED_VALUE"""),1.5) -> 1.5 | G13: =IFERROR(__xludf.DUMMYFUNCTION("""COMPUTED_VALUE"""),"15 GC") -> 15 GC | H13: =IFERROR(__xludf.DUMMYFUNCTION("""COMPUTED_VALUE"""),"1,500 Dollars") -> 1,500 Dollars | I13: =IFERROR(__xludf.DUMMYFUNCTION("""COMPUTED_VALUE"""),"Ammo") -> Ammo | J13: =IFERROR(__xludf.DUMMYFUNCTION("""COMPUTED_VALUE"""),"Yes") -> Yes | L13: =IFERROR(__xludf.DUMMYFUNCTION("""COMPUTED_VALUE"""),"sftp://graphic@103.41.58.141/marketing/WarzTH_LE/Item%20Dict/5.45AK_drum.png") -> sftp://graphic@103.41.58.141/marketing/WarzTH_LE/Item%20Dict/5.45AK_drum.png | N13: =IFERROR(__xludf.DUMMYFUNCTION("""COMPUTED_VALUE"""),"100 rounds drum for AK74 and RPK machine guns") -> 100 rounds drum for AK74 and RPK machine guns
A14: =IFERROR(__xludf.DUMMYFUNCTION("""COMPUTED_VALUE"""),TRUE) -> TRUE | B14: =IFERROR(__xludf.DUMMYFUNCTION("""COMPUTED_VALUE"""),"") | C14: =IFERROR(__xludf.DUMMYFUNCTION("""COMPUTED_VALUE"""),400087.0) -> 400087 | D14: =IFERROR(__xludf.DUMMYFUNCTION("""COMPUTED_VALUE"""),"https://cdn.exe.in.th/marketing/WarzTH_LE/Item%20Dict/5.7_fn_m240_mag.png") -> https://cdn.exe.in.th/marketing/WarzTH_LE/Item%20Dict/5.7_fn_m240_mag.png | E14: =IFERROR(__xludf.DUMMYFUNCTION("""COMPUTED_VALUE"""),"5.7 FN ammo") -> 5.7 FN ammo | F14: =IFERROR(__xludf.DUMMYFUNCTION("""COMPUTED_VALUE"""),1.5) -> 1.5 | G14: =IFERROR(__xludf.DUMMYFUNCTION("""COMPUTED_VALUE"""),"-") -> - | H14: =IFERROR(__xludf.DUMMYFUNCTION("""COMPUTED_VALUE"""),"1,250 Dollars") -> 1,250 Dollars | I14: =IFERROR(__xludf.DUMMYFUNCTION("""COMPUTED_VALUE"""),"Ammo") -> Ammo | J14: =IFERROR(__xludf.DUMMYFUNCTION("""COMPUTED_VALUE"""),"Yes") -> Yes | L14: =IFERROR(__xludf.DUMMYFUNCTION("""COMPUTED_VALUE"""),"sftp://graphic@103.41.58.141/marketing/WarzTH_LE/Item%20Dict/5.7_fn_m240_mag.png") -> sftp://graphic@103.41.58.141/marketing/WarzTH_LE/Item%20Dict/5.7_fn_m240_mag.png | N14: =IFERROR(__xludf.DUMMYFUNCTION("""COMPUTED_VALUE"""),"FN (M240) machine gun round magazine. 20 rounds of 5.7&times;28mm ammo") -> FN (M240) machine gun round magazine. 20 rounds of 5.7&times;28mm ammo
A15: =IFERROR(__xludf.DUMMYFUNCTION("""COMPUTED_VALUE"""),TRUE) -> TRUE | B15: =IFERROR(__xludf.DUMMYFUNCTION("""COMPUTED_VALUE"""),"") | C15: =IFERROR(__xludf.DUMMYFUNCTION("""COMPUTED_VALUE"""),400101.0) -> 400101 | D15: =IFERROR(__xludf.DUMMYFUNCTION("""COMPUTED_VALUE"""),"https://cdn.exe.in.th/marketing/WarzTH_LE/Item%20Dict/7.62AKM_mag.png") -> https://cdn.exe.in.th/marketing/WarzTH_LE/Item%20Dict/7.62AKM_mag.png | E15: =IFERROR(__xludf.DUMMYFUNCTION("""COMPUTED_VALUE"""),"7.62 AKM Mag") -> 7.62 AKM Mag | F15: =IFERROR(__xludf.DUMMYFUNCTION("""COMPUTED_VALUE"""),1.25) -> 1.25 | G15: =IFERROR(__xludf.DUMMYFUNCTION("""COMPUTED_VALUE"""),"-") -> - | H15: =IFERROR(__xludf.DUMMYFUNCTION("""COMPUTED_VALUE"""),"1,000 Dollars") -> 1,000 Dollars | I15: =IFERROR(__xludf.DUMMYFUNCTION("""COMPUTED_VALUE"""),"Ammo") -> Ammo | J15: =IFERROR(__xludf.DUMMYFUNCTION("""COMPUTED_VALUE"""),"Yes") -> Yes | L15: =IFERROR(__xludf.DUMMYFUNCTION("""COMPUTED_VALUE"""),"sftp://graphic@103.41.58.141/marketing/WarzTH_LE/Item%20Dict/7.62AKM_mag.png") -> sftp://graphic@103.41.58.141/marketing/WarzTH_LE/Item%20Dict/7.62AKM_mag.png | N15: =IFERROR(__xludf.DUMMYFUNCTION("""COMPUTED_VALUE"""),"AKM Assault Rifle magazine. 40 7.62x39mm rounds") -> AKM Assault Rifle magazine. 40 7.62x39mm rounds
A16: =IFERROR(__xludf.DUMMYFUNCTION("""COMPUTED_VALUE"""),TRUE) -> TRUE | B16: =IFERROR(__xludf.DUMMYFUNCTION("""COMPUTED_VALUE"""),"") | C16: =IFERROR(__xludf.DUMMYFUNCTION("""COMPUTED_VALUE"""),400071.0) -> 400071 | D16: =IFERROR(__xludf.DUMMYFUNCTION("""COMPUTED_VALUE"""),"https://cdn.exe.in.th/marketing/WarzTH_LE/Item%20Dict/9mm_mag.png") -> https://cdn.exe.in.th/marketing/WarzTH_LE/Item%20Dict/9mm_mag.png | E16: =IFERROR(__xludf.DUMMYFUNCTION("""COMPUTED_VALUE"""),"9mm Mag") -> 9mm Mag | F16: =IFERROR(__xludf.DUMMYFUNCTION("""COMPUTED_VALUE"""),1.0) -> 1 | G16: =IFERROR(__xludf.DUMMYFUNCTION("""COMPUTED_VALUE"""),"-") -> - | H16: =IFERROR(__xludf.DUMMYFUNCTION("""COMPUTED_VALUE"""),"900 Dollars") -> 900 Dollars | I16: =IFERROR(__xludf.DUMMYFUNCTION("""COMPUTED_VALUE"""),"Ammo") -> Ammo | J16: =IFERROR(__xludf.DUMMYFUNCTION("""COMPUTED_VALUE"""),"Yes") -> Yes | L16: =IFERROR(__xludf.DUMMYFUNCTION("""COMPUTED_VALUE"""),"sftp://graphic@103.41.58.141/marketing/WarzTH_LE/Item%20Dict/9mm_mag.png") -> sftp://graphic@103.41.58.141/marketing/WarzTH_LE/Item%20Dict/9mm_mag.png | N16: =IFERROR(__xludf.DUMMYFUNCTION("""COMPUTED_VALUE"""),"""15 rounds magazine of 9mm ammo for use with: B92, B93R and Jericho handguns""") -> "15 rounds magazine of 9mm ammo for use with: B92, B93R and Jericho handguns"
A17: =IFERROR(__xludf.DUMMYFUNCTION("""COMPUTED_VALUE"""),TRUE) -> TRUE | B17: =IFERROR(__xludf.DUMMYFUNCTION("""COMPUTED_VALUE"""),"") | C17: =IFERROR(__xludf.DUMMYFUNCTION("""COMPUTED_VALUE"""),400034.0) -> 400034 | D17: =IFERROR(__xludf.DUMMYFUNCTION("""COMPUTED_VALUE"""),"https://cdn.exe.in.th/marketing/WarzTH_LE/Item%20Dict/9x19_para_mag.png") -> https://cdn.exe.in.th/marketing/WarzTH_LE/Item%20Dict/9x19_para_mag.png | E17: =IFERROR(__xludf.DUMMYFUNCTION("""COMPUTED_VALUE"""),"9x19 Para Mag") -> 9x19 Para Mag | F17: =IFERROR(__xludf.DUMMYFUNCTION("""COMPUTED_VALUE"""),0.3) -> 0.3 | G17: =IFERROR(__xludf.DUMMYFUNCTION("""COMPUTED_VALUE"""),"-") -> - | H17: =IFERROR(__xludf.DUMMYFUNCTION("""COMPUTED_VALUE"""),"250 Dollars") -> 250 Dollars | I17: =IFERROR(__xludf.DUMMYFUNCTION("""COMPUTED_VALUE"""),"Ammo") -> Ammo | J17: =IFERROR(__xludf.DUMMYFUNCTION("""COMPUTED_VALUE"""),"Yes") -> Yes | L17: =IFERROR(__xludf.DUMMYFUNCTION("""COMPUTED_VALUE"""),"sftp://graphic@103.41.58.141/marketing/WarzTH_LE/Item%20Dict/9x19_para_mag.png") -> sftp://graphic@103.41.58.141/marketing/WarzTH_LE/Item%20Dict/9x19_para_mag.png | N17: =IFERROR(__xludf.DUMMYFUNCTION("""COMPUTED_VALUE"""),"18 rounds 9x19mm Parabellum magazine specially designed for Sig Sauer P226 handgun") -> 18 rounds 9x19mm Parabellum magazine specially designed for Sig Sauer P226 handgun
A18: =IFERROR(__xludf.DUMMYFUNCTION("""COMPUTED_VALUE"""),TRUE) -> TRUE | B18: =IFERROR(__xludf.DUMMYFUNCTION("""COMPUTED_VALUE"""),"") | C18: =IFERROR(__xludf.DUMMYFUNCTION("""COMPUTED_VALUE"""),101200.0) -> 101200 | D18: =IFERROR(__xludf.DUMMYFUNCTION("""COMPUTED_VALUE"""),"https://cdn.exe.in.th/marketing/WarzTH_LE/Item%20Dict/aa_12.png") -> https://cdn.exe.in.th/marketing/WarzTH_LE/Item%20Dict/aa_12.png | E18: =IFERROR(__xludf.DUMMYFUNCTION("""COMPUTED_VALUE"""),"AA-12") -> AA-12 | F18: =IFERROR(__xludf.DUMMYFUNCTION("""COMPUTED_VALUE"""),5.0) -> 5 | G18: =IFERROR(__xludf.DUMMYFUNCTION("""COMPUTED_VALUE"""),"-") -> - | H18: =IFERROR(__xludf.DUMMYFUNCTION("""COMPUTED_VALUE"""),"-") -> - | I18: =IFERROR(__xludf.DUMMYFUNCTION("""COMPUTED_VALUE"""),"Weapon") -> Weapon | J18: =IFERROR(__xludf.DUMMYFUNCTION("""COMPUTED_VALUE"""),"No") -> No | K18: =IFERROR(__xludf.DUMMYFUNCTION("""COMPUTED_VALUE"""),"C") -> C | L18: =IFERROR(__xludf.DUMMYFUNCTION("""COMPUTED_VALUE"""),"sftp://graphic@103.41.58.141/marketing/WarzTH_LE/Item%20Dict/aa_12.png") -> sftp://graphic@103.41.58.141/marketing/WarzTH_LE/Item%20Dict/aa_12.png | N18: =IFERROR(__xludf.DUMMYFUNCTION("""COMPUTED_VALUE"""),"The AA-12 gauge automatic shotgun was designed to fire 12 gauge rounds from a 20 round storage system. It causes a reasonable amount of damage per round.") -> The AA-12 gauge automatic shotgun was designed to fire 12 gauge rounds from a 20 round storage system. It causes a reasonable amount of damage per round.
A19: =IFERROR(__xludf.DUMMYFUNCTION("""COMPUTED_VALUE"""),TRUE) -> TRUE | B19: =IFERROR(__xludf.DUMMYFUNCTION("""COMPUTED_VALUE"""),"") | C19: =IFERROR(__xludf.DUMMYFUNCTION("""COMPUTED_VALUE"""),400050.0) -> 400050 | D19: =IFERROR(__xludf.DUMMYFUNCTION("""COMPUTED_VALUE"""),"https://cdn.exe.in.th/marketing/WarzTH_LE/Item%20Dict/aa_12_drum.png") -> https://cdn.exe.in.th/marketing/WarzTH_LE/Item%20Dict/aa_12_drum.png | E19: =IFERROR(__xludf.DUMMYFUNCTION("""COMPUTED_VALUE"""),"AA-12 Drum") -> AA-12 Drum | F19: =IFERROR(__xludf.DUMMYFUNCTION("""COMPUTED_VALUE"""),1.5) -> 1.5 | G19: =IFERROR(__xludf.DUMMYFUNCTION("""COMPUTED_VALUE"""),"-") -> - | H19: =IFERROR(__xludf.DUMMYFUNCTION("""COMPUTED_VALUE"""),"1,250 Dollars") -> 1,250 Dollars | I19: =IFERROR(__xludf.DUMMYFUNCTION("""COMPUTED_VALUE"""),"Ammo") -> Ammo | J19: =IFERROR(__xludf.DUMMYFUNCTION("""COMPUTED_VALUE"""),"Yes") -> Yes | L19: =IFERROR(__xludf.DUMMYFUNCTION("""COMPUTED_VALUE"""),"sftp://graphic@103.41.58.141/marketing/WarzTH_LE/Item%20Dict/aa_12_drum.png") -> sftp://graphic@103.41.58.141/marketing/WarzTH_LE/Item%20Dict/aa_12_drum.png | N19: =IFERROR(__xludf.DUMMYFUNCTION("""COMPUTED_VALUE"""),"12 gauge 20 rounds drum magazine for AA-12 shotgun") -> 12 gauge 20 rounds drum magazine for AA-12 shotgun
A20: =IFERROR(__xludf.DUMMYFUNCTION("""COMPUTED_VALUE"""),TRUE) -> TRUE | B20: =IFERROR(__xludf.DUMMYFUNCTION("""COMPUTED_VALUE"""),"") | C20: =IFERROR(__xludf.DUMMYFUNCTION("""COMPUTED_VALUE"""),400003.0) -> 400003 | D20: =IFERROR(__xludf.DUMMYFUNCTION("""COMPUTED_VALUE"""),"https://cdn.exe.in.th/marketing/WarzTH_LE/Item%20Dict/acog.png") -> https://cdn.exe.in.th/marketing/WarzTH_LE/Item%20Dict/acog.png | E20: =IFERROR(__xludf.DUMMYFUNCTION("""COMPUTED_VALUE"""),"ACOG") -> ACOG | F20: =IFERROR(__xludf.DUMMYFUNCTION("""COMPUTED_VALUE"""),2.0) -> 2 | G20: =IFERROR(__xludf.DUMMYFUNCTION("""COMPUTED_VALUE"""),"20 GC") -> 20 GC | H20: =IFERROR(__xludf.DUMMYFUNCTION("""COMPUTED_VALUE"""),"2,000 Dollars") -> 2,000 Dollars | I20: =IFERROR(__xludf.DUMMYFUNCTION("""COMPUTED_VALUE"""),"Attachment") -> Attachment | J20: =IFERROR(__xludf.DUMMYFUNCTION("""COMPUTED_VALUE"""),"No") -> No | L20: =IFERROR(__xludf.DUMMYFUNCTION("""COMPUTED_VALUE"""),"sftp://graphic@103.41.58.141/marketing/WarzTH_LE/Item%20Dict/acog.png") -> sftp://graphic@103.41.58.141/marketing/WarzTH_LE/Item%20Dict/acog.png | N20: =IFERROR(__xludf.DUMMYFUNCTION("""COMPUTED_VALUE"""),"The Acog is a rail mounted telescopic sight used to extend a shooters accuracy on medium to long range shots.") -> The Acog is a rail mounted telescopic sight used to extend a shooters accuracy on medium to long range shots.
A21: =IFERROR(__xludf.DUMMYFUNCTION("""COMPUTED_VALUE"""),TRUE) -> TRUE | B21: =IFERROR(__xludf.DUMMYFUNCTION("""COMPUTED_VALUE"""),"") | C21: =IFERROR(__xludf.DUMMYFUNCTION("""COMPUTED_VALUE"""),101323.0) -> 101323 | D21: =IFERROR(__xludf.DUMMYFUNCTION("""COMPUTED_VALUE"""),"https://cdn.exe.in.th/marketing/WarzTH_LE/Item%20Dict/air_horn.png") -> https://cdn.exe.in.th/marketing/WarzTH_LE/Item%20Dict/air_horn.png | E21: =IFERROR(__xludf.DUMMYFUNCTION("""COMPUTED_VALUE"""),"Air horn") -> Air horn | F21: =IFERROR(__xludf.DUMMYFUNCTION("""COMPUTED_VALUE"""),3.0) -> 3 | G21: =IFERROR(__xludf.DUMMYFUNCTION("""COMPUTED_VALUE"""),"-") -> - | H21: =IFERROR(__xludf.DUMMYFUNCTION("""COMPUTED_VALUE"""),"-") -> - | I21: =IFERROR(__xludf.DUMMYFUNCTION("""COMPUTED_VALUE"""),"Consumable") -> Consumable | J21: =IFERROR(__xludf.DUMMYFUNCTION("""COMPUTED_VALUE"""),"Yes") -> Yes | L21: =IFERROR(__xludf.DUMMYFUNCTION("""COMPUTED_VALUE"""),"sftp://graphic@103.41.58.141/marketing/WarzTH_LE/Item%20Dict/air_horn.png") -> sftp://graphic@103.41.58.141/marketing/WarzTH_LE/Item%20Dict/air_horn.png | N21: =IFERROR(__xludf.DUMMYFUNCTION("""COMPUTED_VALUE"""),"Do your friends keep getting attacked? Be the hero and blow your air horn to make the infected come after you instead.") -> Do your friends keep getting attacked? Be the hero and blow your air horn to make the infected come after you instead.
A22: =IFERROR(__xludf.DUMMYFUNCTION("""COMPUTED_VALUE"""),TRUE) -> TRUE | B22: =IFERROR(__xludf.DUMMYFUNCTION("""COMPUTED_VALUE"""),"") | C22: =IFERROR(__xludf.DUMMYFUNCTION("""COMPUTED_VALUE"""),101022.0) -> 101022 | D22: =IFERROR(__xludf.DUMMYFUNCTION("""COMPUTED_VALUE"""),"https://cdn.exe.in.th/marketing/WarzTH_LE/Item%20Dict/ak_74m.png") -> https://cdn.exe.in.th/marketing/WarzTH_LE/Item%20Dict/ak_74m.png | E22: =IFERROR(__xludf.DUMMYFUNCTION("""COMPUTED_VALUE"""),"AK-74M") -> AK-74M | F22: =IFERROR(__xludf.DUMMYFUNCTION("""COMPUTED_VALUE"""),4.0) -> 4 | G22: =IFERROR(__xludf.DUMMYFUNCTION("""COMPUTED_VALUE"""),"-") -> - | H22: =IFERROR(__xludf.DUMMYFUNCTION("""COMPUTED_VALUE"""),"-") -> - | I22: =IFERROR(__xludf.DUMMYFUNCTION("""COMPUTED_VALUE"""),"Weapon") -> Weapon | J22: =IFERROR(__xludf.DUMMYFUNCTION("""COMPUTED_VALUE"""),"No") -> No | K22: =IFERROR(__xludf.DUMMYFUNCTION("""COMPUTED_VALUE"""),"B") -> B | L22: =IFERROR(__xludf.DUMMYFUNCTION("""COMPUTED_VALUE"""),"sftp://graphic@103.41.58.141/marketing/WarzTH_LE/Item%20Dict/ak_74m.png") -> sftp://graphic@103.41.58.141/marketing/WarzTH_LE/Item%20Dict/ak_74m.png | N22: =IFERROR(__xludf.DUMMYFUNCTION("""COMPUTED_VALUE"""),"The AK-74M assault rifle is an upgrade of the AK 74 design with a slightly increased rate of fire. It fires a 5.45 x 39 mm round accurately at medium ranges.") -> The AK-74M assault rifle is an upgrade of the AK 74 design with a slightly increased rate of fire. It fires a 5.45 x 39 mm round accurately at medium ranges.
A23: =IFERROR(__xludf.DUMMYFUNCTION("""COMPUTED_VALUE"""),TRUE) -> TRUE | B23: =IFERROR(__xludf.DUMMYFUNCTION("""COMPUTED_VALUE"""),"") | C23: =IFERROR(__xludf.DUMMYFUNCTION("""COMPUTED_VALUE"""),101032.0) -> 101032 | D23: =IFERROR(__xludf.DUMMYFUNCTION("""COMPUTED_VALUE"""),"https://cdn.exe.in.th/marketing/WarzTH_LE/Item%20Dict/akm.png") -> https://cdn.exe.in.th/marketing/WarzTH_LE/Item%20Dict/akm.png | E23: =IFERROR(__xludf.DUMMYFUNCTION("""COMPUTED_VALUE"""),"AKM") -> AKM | F23: =IFERROR(__xludf.DUMMYFUNCTION("""COMPUTED_VALUE"""),2.0) -> 2 | G23: =IFERROR(__xludf.DUMMYFUNCTION("""COMPUTED_VALUE"""),"-") -> - | H23: =IFERROR(__xludf.DUMMYFUNCTION("""COMPUTED_VALUE"""),"-") -> - | I23: =IFERROR(__xludf.DUMMYFUNCTION("""COMPUTED_VALUE"""),"Weapon") -> Weapon | J23: =IFERROR(__xludf.DUMMYFUNCTION("""COMPUTED_VALUE"""),"No") -> No | K23: =IFERROR(__xludf.DUMMYFUNCTION("""COMPUTED_VALUE"""),"B") -> B | L23: =IFERROR(__xludf.DUMMYFUNCTION("""COMPUTED_VALUE"""),"sftp://graphic@103.41.58.141/marketing/WarzTH_LE/Item%20Dict/akm.png") -> sftp://graphic@103.41.58.141/marketing/WarzTH_LE/Item%20Dict/akm.png | N23: =IFERROR(__xludf.DUMMYFUNCTION("""COMPUTED_VALUE"""),"The AKM is an assault rifle that was designed as a simplified version of the AK-47 rifle. It fires a 7.62 x 39 mm round and is relatively effective at medium ranges.") -> The AKM is an assault rifle that was designed as a simplified version of the AK-47 rifle. It fires a 7.62 x 39 mm round and is relatively effective at medium ranges.
A24: =IFERROR(__xludf.DUMMYFUNCTION("""COMPUTED_VALUE"""),TRUE) -> TRUE | B24: =IFERROR(__xludf.DUMMYFUNCTION("""COMPUTED_VALUE"""),"") | C24: =IFERROR(__xludf.DUMMYFUNCTION("""COMPUTED_VALUE"""),101035.0) -> 101035 | D24: =IFERROR(__xludf.DUMMYFUNCTION("""COMPUTED_VALUE"""),"https://cdn.exe.in.th/marketing/WarzTH_LE/Item%20Dict/aks_74u.png") -> https://cdn.exe.in.th/marketing/WarzTH_LE/Item%20Dict/aks_74u.png | E24: =IFERROR(__xludf.DUMMYFUNCTION("""COMPUTED_VALUE"""),"AKS-74U") -> AKS-74U | F24: =IFERROR(__xludf.DUMMYFUNCTION("""COMPUTED_VALUE"""),2.0) -> 2 | G24: =IFERROR(__xludf.DUMMYFUNCTION("""COMPUTED_VALUE"""),"-") -> - | H24: =IFERROR(__xludf.DUMMYFUNCTION("""COMPUTED_VALUE"""),"-") -> - | I24: =IFERROR(__xludf.DUMMYFUNCTION("""COMPUTED_VALUE"""),"Weapon") -> Weapon | J24: =IFERROR(__xludf.DUMMYFUNCTION("""COMPUTED_VALUE"""),"No") -> No | K24: =IFERROR(__xludf.DUMMYFUNCTION("""COMPUTED_VALUE"""),"B") -> B | L24: =IFERROR(__xludf.DUMMYFUNCTION("""COMPUTED_VALUE"""),"sftp://graphic@103.41.58.141/marketing/WarzTH_LE/Item%20Dict/aks_74u.png") -> sftp://graphic@103.41.58.141/marketing/WarzTH_LE/Item%20Dict/aks_74u.png | N24: =IFERROR(__xludf.DUMMYFUNCTION("""COMPUTED_VALUE"""),"The AKS-74U is a shortened gas operated carbine version of the AKS-74 assault rifle. It fires a 5.45 x 39 mm round and is very effective at medium ranges.") -> The AKS-74U is a shortened gas operated carbine version of the AKS-74 assault rifle. It fires a 5.45 x 39 mm round and is very effective at medium ranges.
A25: =IFERROR(__xludf.DUMMYFUNCTION("""COMPUTED_VALUE"""),TRUE) -> TRUE | B25: =IFERROR(__xludf.DUMMYFUNCTION("""COMPUTED_VALUE"""),"") | C25: =IFERROR(__xludf.DUMMYFUNCTION("""COMPUTED_VALUE"""),20185.0) -> 20185 | D25: =IFERROR(__xludf.DUMMYFUNCTION("""COMPUTED_VALUE"""),"https://cdn.exe.in.th/marketing/WarzTH_LE/Item%20Dict/alice_rucksack.png") -> https://cdn.exe.in.th/marketing/WarzTH_LE/Item%20Dict/alice_rucksack.png | E25: =IFERROR(__xludf.DUMMYFUNCTION("""COMPUTED_VALUE"""),"ALICE Rucksack") -> ALICE Rucksack | F25: =IFERROR(__xludf.DUMMYFUNCTION("""COMPUTED_VALUE"""),2.5) -> 2.5 | G25: =IFERROR(__xludf.DUMMYFUNCTION("""COMPUTED_VALUE"""),"25 GC") -> 25 GC | H25: =IFERROR(__xludf.DUMMYFUNCTION("""COMPUTED_VALUE"""),"3,000 Dollars") -> 3,000 Dollars | I25: =IFERROR(__xludf.DUMMYFUNCTION("""COMPUTED_VALUE"""),"Equipment") -> Equipment | J25: =IFERROR(__xludf.DUMMYFUNCTION("""COMPUTED_VALUE"""),"No") -> No | L25: =IFERROR(__xludf.DUMMYFUNCTION("""COMPUTED_VALUE"""),"sftp://graphic@103.41.58.141/marketing/WarzTH_LE/Item%20Dict/alice_rucksack.png") -> sftp://graphic@103.41.58.141/marketing/WarzTH_LE/Item%20Dict/alice_rucksack.png | N25: =IFERROR(__xludf.DUMMYFUNCTION("""COMPUTED_VALUE"""),"Large backpack that fits everything you will need. The All-purpose Lightweight Individual Carrying Equipment. Dont forget the poo tickets!") -> Large backpack that fits everything you will need. The All-purpose Lightweight Individual Carrying Equipment. Dont forget the poo tickets!
A26: =IFERROR(__xludf.DUMMYFUNCTION("""COMPUTED_VALUE"""),TRUE) -> TRUE | B26: =IFERROR(__xludf.DUMMYFUNCTION("""COMPUTED_VALUE"""),"") | C26: =IFERROR(__xludf.DUMMYFUNCTION("""COMPUTED_VALUE"""),400145.0) -> 400145 | D26: =IFERROR(__xludf.DUMMYFUNCTION("""COMPUTED_VALUE"""),"https://cdn.exe.in.th/marketing/WarzTH_LE/Item%20Dict/anaconda_mag.png") -> https://cdn.exe.in.th/marketing/WarzTH_LE/Item%20Dict/anaconda_mag.png | E26: =IFERROR(__xludf.DUMMYFUNCTION("""COMPUTED_VALUE"""),"Anaconda rounds") -> Anaconda rounds | F26: =IFERROR(__xludf.DUMMYFUNCTION("""COMPUTED_VALUE"""),0.6) -> 0.6 | G26: =IFERROR(__xludf.DUMMYFUNCTION("""COMPUTED_VALUE"""),"6 GC") -> 6 GC | H26: =IFERROR(__xludf.DUMMYFUNCTION("""COMPUTED_VALUE"""),"500 Dollars") -> 500 Dollars | I26: =IFERROR(__xludf.DUMMYFUNCTION("""COMPUTED_VALUE"""),"Ammo") -> Ammo | J26: =IFERROR(__xludf.DUMMYFUNCTION("""COMPUTED_VALUE"""),"Yes") -> Yes | L26: =IFERROR(__xludf.DUMMYFUNCTION("""COMPUTED_VALUE"""),"sftp://graphic@103.41.58.141/marketing/WarzTH_LE/Item%20Dict/anaconda_mag.png") -> sftp://graphic@103.41.58.141/marketing/WarzTH_LE/Item%20Dict/anaconda_mag.png | N26: =IFERROR(__xludf.DUMMYFUNCTION("""COMPUTED_VALUE"""),"6 rounds for the Anaconda") -> 6 rounds for the Anaconda
A27: =IFERROR(__xludf.DUMMYFUNCTION("""COMPUTED_VALUE"""),TRUE) -> TRUE | B27: =IFERROR(__xludf.DUMMYFUNCTION("""COMPUTED_VALUE"""),"") | C27: =IFERROR(__xludf.DUMMYFUNCTION("""COMPUTED_VALUE"""),101256.0) -> 101256 | D27: =IFERROR(__xludf.DUMMYFUNCTION("""COMPUTED_VALUE"""),"https://cdn.exe.in.th/marketing/WarzTH_LE/Item%20Dict/anitibiotics.png") -> https://cdn.exe.in.th/marketing/WarzTH_LE/Item%20Dict/anitibiotics.png | E27: =IFERROR(__xludf.DUMMYFUNCTION("""COMPUTED_VALUE"""),"Antibiotics") -> Antibiotics | F27: =IFERROR(__xludf.DUMMYFUNCTION("""COMPUTED_VALUE"""),0.5) -> 0.5 | G27: =IFERROR(__xludf.DUMMYFUNCTION("""COMPUTED_VALUE"""),"5 GC") -> 5 GC | H27: =IFERROR(__xludf.DUMMYFUNCTION("""COMPUTED_VALUE"""),"500 Dollars") -> 500 Dollars | I27: =IFERROR(__xludf.DUMMYFUNCTION("""COMPUTED_VALUE"""),"Consumable") -> Consumable | J27: =IFERROR(__xludf.DUMMYFUNCTION("""COMPUTED_VALUE"""),"Yes") -> Yes | L27: =IFERROR(__xludf.DUMMYFUNCTION("""COMPUTED_VALUE"""),"sftp://graphic@103.41.58.141/marketing/WarzTH_LE/Item%20Dict/anitibiotics.png") -> sftp://graphic@103.41.58.141/marketing/WarzTH_LE/Item%20Dict/anitibiotics.png | N27: =IFERROR(__xludf.DUMMYFUNCTION("""COMPUTED_VALUE"""),"Over the counter antibiotics that aid in curing colds and other minor ailments.") -> Over the counter antibiotics that aid in curing colds and other minor ailments.
A28: =IFERROR(__xludf.DUMMYFUNCTION("""COMPUTED_VALUE"""),TRUE) -> TRUE | B28: =IFERROR(__xludf.DUMMYFUNCTION("""COMPUTED_VALUE"""),"") | C28: =IFERROR(__xludf.DUMMYFUNCTION("""COMPUTED_VALUE"""),400140.0) -> 400140 | D28: =IFERROR(__xludf.DUMMYFUNCTION("""COMPUTED_VALUE"""),"https://cdn.exe.in.th/marketing/WarzTH_LE/Item%20Dict/arrow_explo.png") -> https://cdn.exe.in.th/marketing/WarzTH_LE/Item%20Dict/arrow_explo.png | E28: =IFERROR(__xludf.DUMMYFUNCTION("""COMPUTED_VALUE"""),"Arrow") -> Arrow | F28: =IFERROR(__xludf.DUMMYFUNCTION("""COMPUTED_VALUE"""),0.2) -> 0.2 | G28: =IFERROR(__xludf.DUMMYFUNCTION("""COMPUTED_VALUE"""),"2 GC") -> 2 GC | H28: =IFERROR(__xludf.DUMMYFUNCTION("""COMPUTED_VALUE"""),"200 Dollars") -> 200 Dollars | I28: =IFERROR(__xludf.DUMMYFUNCTION("""COMPUTED_VALUE"""),"Ammo") -> Ammo | J28: =IFERROR(__xludf.DUMMYFUNCTION("""COMPUTED_VALUE"""),"Yes") -> Yes | L28: =IFERROR(__xludf.DUMMYFUNCTION("""COMPUTED_VALUE"""),"sftp://graphic@103.41.58.141/marketing/WarzTH_LE/Item%20Dict/arrow_explo.png") -> sftp://graphic@103.41.58.141/marketing/WarzTH_LE/Item%20Dict/arrow_explo.png | N28: =IFERROR(__xludf.DUMMYFUNCTION("""COMPUTED_VALUE"""),"Explosive bolt (arrow) for the crossbow") -> Explosive bolt (arrow) for the crossbow
A29: =IFERROR(__xludf.DUMMYFUNCTION("""COMPUTED_VALUE"""),TRUE) -> TRUE | B29: =IFERROR(__xludf.DUMMYFUNCTION("""COMPUTED_VALUE"""),"") | C29: =IFERROR(__xludf.DUMMYFUNCTION("""COMPUTED_VALUE"""),20201.0) -> 20201 | D29: =IFERROR(__xludf.DUMMYFUNCTION("""COMPUTED_VALUE"""),"https://cdn.exe.in.th/marketing/WarzTH_LE/Item%20Dict/asian_male.png") -> https://cdn.exe.in.th/marketing/WarzTH_LE/Item%20Dict/asian_male.png | E29: =IFERROR(__xludf.DUMMYFUNCTION("""COMPUTED_VALUE"""),"Asian Male") -> Asian Male | F29: =IFERROR(__xludf.DUMMYFUNCTION("""COMPUTED_VALUE"""),"-") -> - | G29: =IFERROR(__xludf.DUMMYFUNCTION("""COMPUTED_VALUE"""),"-") -> - | H29: =IFERROR(__xludf.DUMMYFUNCTION("""COMPUTED_VALUE"""),"-") -> - | I29: =IFERROR(__xludf.DUMMYFUNCTION("""COMPUTED_VALUE"""),"Character") -> Character | J29: =IFERROR(__xludf.DUMMYFUNCTION("""COMPUTED_VALUE"""),"No") -> No | L29: =IFERROR(__xludf.DUMMYFUNCTION("""COMPUTED_VALUE"""),"sftp://graphic@103.41.58.141/marketing/WarzTH_LE/Item%20Dict/asian_male.png") -> sftp://graphic@103.41.58.141/marketing/WarzTH_LE/Item%20Dict/asian_male.png | N29: =IFERROR(__xludf.DUMMYFUNCTION("""COMPUTED_VALUE"""),"-") -> -
A30: =IFERROR(__xludf.DUMMYFUNCTION("""COMPUTED_VALUE"""),TRUE) -> TRUE | B30: =IFERROR(__xludf.DUMMYFUNCTION("""COMPUTED_VALUE"""),"") | C30: =IFERROR(__xludf.DUMMYFUNCTION("""COMPUTED_VALUE"""),20193.0) -> 20193 | D30: =IFERROR(__xludf.DUMMYFUNCTION("""COMPUTED_VALUE"""),"https://cdn.exe.in.th/marketing/WarzTH_LE/Item%20Dict/average_joe.png") -> https://cdn.exe.in.th/marketing/WarzTH_LE/Item%20Dict/average_joe.png | E30: =IFERROR(__xludf.DUMMYFUNCTION("""COMPUTED_VALUE"""),"Average Joe") -> Average Joe | F30: =IFERROR(__xludf.DUMMYFUNCTION("""COMPUTED_VALUE"""),90.0) -> 90 | G30: =IFERROR(__xludf.DUMMYFUNCTION("""COMPUTED_VALUE"""),"900 GC") -> 900 GC | H30: =IFERROR(__xludf.DUMMYFUNCTION("""COMPUTED_VALUE"""),"72,000 Dollars") -> 72,000 Dollars | I30: =IFERROR(__xludf.DUMMYFUNCTION("""COMPUTED_VALUE"""),"Character") -> Character | J30: =IFERROR(__xludf.DUMMYFUNCTION("""COMPUTED_VALUE"""),"No") -> No | L30: =IFERROR(__xludf.DUMMYFUNCTION("""COMPUTED_VALUE"""),"sftp://graphic@103.41.58.141/marketing/WarzTH_LE/Item%20Dict/average_joe.png") -> sftp://graphic@103.41.58.141/marketing/WarzTH_LE/Item%20Dict/average_joe.png | N30: =IFERROR(__xludf.DUMMYFUNCTION("""COMPUTED_VALUE"""),"-") -> -
A31: =IFERROR(__xludf.DUMMYFUNCTION("""COMPUTED_VALUE"""),TRUE) -> TRUE | B31: =IFERROR(__xludf.DUMMYFUNCTION("""COMPUTED_VALUE"""),"") | C31: =IFERROR(__xludf.DUMMYFUNCTION("""COMPUTED_VALUE"""),400043.0) -> 400043 | D31: =IFERROR(__xludf.DUMMYFUNCTION("""COMPUTED_VALUE"""),"https://cdn.exe.in.th/marketing/WarzTH_LE/Item%20Dict/.338_ammo.png") -> https://cdn.exe.in.th/marketing/WarzTH_LE/Item%20Dict/.338_ammo.png | E31: =IFERROR(__xludf.DUMMYFUNCTION("""COMPUTED_VALUE"""),"AWM .338 Magnum ammo") -> AWM .338 Magnum ammo | F31: =IFERROR(__xludf.DUMMYFUNCTION("""COMPUTED_VALUE"""),"-") -> - | G31: =IFERROR(__xludf.DUMMYFUNCTION("""COMPUTED_VALUE"""),"-") -> - | H31: =IFERROR(__xludf.DUMMYFUNCTION("""COMPUTED_VALUE"""),"-") -> - | I31: =IFERROR(__xludf.DUMMYFUNCTION("""COMPUTED_VALUE"""),"Ammo") -> Ammo | J31: =IFERROR(__xludf.DUMMYFUNCTION("""COMPUTED_VALUE"""),"Yes") -> Yes | L31: =IFERROR(__xludf.DUMMYFUNCTION("""COMPUTED_VALUE"""),"sftp://graphic@103.41.58.141/marketing/WarzTH_LE/Item%20Dict/.338_ammo.png") -> sftp://graphic@103.41.58.141/marketing/WarzTH_LE/Item%20Dict/.338_ammo.png | N31: =IFERROR(__xludf.DUMMYFUNCTION("""COMPUTED_VALUE"""),"8.6x70mm specialized rimless bottlenecked centerfire 10 rounds cartridge. Specifically designed for AWM rifle") -> 8.6x70mm specialized rimless bottlenecked centerfire 10 rounds cartridge. Specifically designed for AWM rifle
A32: =IFERROR(__xludf.DUMMYFUNCTION("""COMPUTED_VALUE"""),TRUE) -> TRUE | B32: =IFERROR(__xludf.DUMMYFUNCTION("""COMPUTED_VALUE"""),"") | C32: =IFERROR(__xludf.DUMMYFUNCTION("""COMPUTED_VALUE"""),101087.0) -> 101087 | D32: =IFERROR(__xludf.DUMMYFUNCTION("""COMPUTED_VALUE"""),"https://cdn.exe.in.th/marketing/WarzTH_LE/Item%20Dict/aw_magnum.png") -> https://cdn.exe.in.th/marketing/WarzTH_LE/Item%20Dict/aw_magnum.png | E32: =IFERROR(__xludf.DUMMYFUNCTION("""COMPUTED_VALUE"""),"AW Magnum") -> AW Magnum | F32: =IFERROR(__xludf.DUMMYFUNCTION("""COMPUTED_VALUE"""),12000.0) -> 12000 | G32: =IFERROR(__xludf.DUMMYFUNCTION("""COMPUTED_VALUE"""),"-") -> - | H32: =IFERROR(__xludf.DUMMYFUNCTION("""COMPUTED_VALUE"""),"-") -> - | I32: =IFERROR(__xludf.DUMMYFUNCTION("""COMPUTED_VALUE"""),"Weapon") -> Weapon | J32: =IFERROR(__xludf.DUMMYFUNCTION("""COMPUTED_VALUE"""),"No") -> No | K32: =IFERROR(__xludf.DUMMYFUNCTION("""COMPUTED_VALUE"""),"SR") -> SR | L32: =IFERROR(__xludf.DUMMYFUNCTION("""COMPUTED_VALUE"""),"sftp://graphic@103.41.58.141/marketing/WarzTH_LE/Item%20Dict/aw_magnum.png") -> sftp://graphic@103.41.58.141/marketing/WarzTH_LE/Item%20Dict/aw_magnum.png | N32: =IFERROR(__xludf.DUMMYFUNCTION("""COMPUTED_VALUE"""),"The AWM sniper rifle fires a custom .338W magnum round with devastating accuracy and effect. Each of its rounds deal a very high amount of damage.") -> The AWM sniper rifle fires a custom .338W magnum round with devastating accuracy and effect. Each of its rounds deal a very high amount of damage.
A33: =IFERROR(__xludf.DUMMYFUNCTION("""COMPUTED_VALUE"""),TRUE) -> TRUE | B33: =IFERROR(__xludf.DUMMYFUNCTION("""COMPUTED_VALUE"""),"") | C33: =IFERROR(__xludf.DUMMYFUNCTION("""COMPUTED_VALUE"""),101111.0) -> 101111 | D33: =IFERROR(__xludf.DUMMYFUNCTION("""COMPUTED_VALUE"""),"https://cdn.exe.in.th/marketing/WarzTH_LE/Item%20Dict/b92.png") -> https://cdn.exe.in.th/marketing/WarzTH_LE/Item%20Dict/b92.png | E33: =IFERROR(__xludf.DUMMYFUNCTION("""COMPUTED_VALUE"""),"B92") -> B92 | F33: =IFERROR(__xludf.DUMMYFUNCTION("""COMPUTED_VALUE"""),0.5) -> 0.5 | G33: =IFERROR(__xludf.DUMMYFUNCTION("""COMPUTED_VALUE"""),"-") -> - | H33: =IFERROR(__xludf.DUMMYFUNCTION("""COMPUTED_VALUE"""),"-") -> - | I33: =IFERROR(__xludf.DUMMYFUNCTION("""COMPUTED_VALUE"""),"Weapon") -> Weapon | J33: =IFERROR(__xludf.DUMMYFUNCTION("""COMPUTED_VALUE"""),"No") -> No | K33: =IFERROR(__xludf.DUMMYFUNCTION("""COMPUTED_VALUE"""),"C") -> C | L33: =IFERROR(__xludf.DUMMYFUNCTION("""COMPUTED_VALUE"""),"sftp://graphic@103.41.58.141/marketing/WarzTH_LE/Item%20Dict/b92.png") -> sftp://graphic@103.41.58.141/marketing/WarzTH_LE/Item%20Dict/b92.png | N33: =IFERROR(__xludf.DUMMYFUNCTION("""COMPUTED_VALUE"""),"The B92 handgun was specially designed to fire a 9mm round and is reasonably effective agains close range targets.") -> The B92 handgun was specially designed to fire a 9mm round and is reasonably effective agains close range targets.
A34: =IFERROR(__xludf.DUMMYFUNCTION("""COMPUTED_VALUE"""),TRUE) -> TRUE | B34: =IFERROR(__xludf.DUMMYFUNCTION("""COMPUTED_VALUE"""),"") | C34: =IFERROR(__xludf.DUMMYFUNCTION("""COMPUTED_VALUE"""),101112.0) -> 101112 | D34: =IFERROR(__xludf.DUMMYFUNCTION("""COMPUTED_VALUE"""),"https://cdn.exe.in.th/marketing/WarzTH_LE/Item%20Dict/b93r.png") -> https://cdn.exe.in.th/marketing/WarzTH_LE/Item%20Dict/b93r.png | E34: =IFERROR(__xludf.DUMMYFUNCTION("""COMPUTED_VALUE"""),"B93R") -> B93R | F34: =IFERROR(__xludf.DUMMYFUNCTION("""COMPUTED_VALUE"""),0.5) -> 0.5 | G34: =IFERROR(__xludf.DUMMYFUNCTION("""COMPUTED_VALUE"""),"-") -> - | H34: =IFERROR(__xludf.DUMMYFUNCTION("""COMPUTED_VALUE"""),"-") -> - | I34: =IFERROR(__xludf.DUMMYFUNCTION("""COMPUTED_VALUE"""),"Weapon") -> Weapon | J34: =IFERROR(__xludf.DUMMYFUNCTION("""COMPUTED_VALUE"""),"No") -> No | K34: =IFERROR(__xludf.DUMMYFUNCTION("""COMPUTED_VALUE"""),"C") -> C | L34: =IFERROR(__xludf.DUMMYFUNCTION("""COMPUTED_VALUE"""),"sftp://graphic@103.41.58.141/marketing/WarzTH_LE/Item%20Dict/b93r.png") -> sftp://graphic@103.41.58.141/marketing/WarzTH_LE/Item%20Dict/b93r.png | N34: =IFERROR(__xludf.DUMMYFUNCTION("""COMPUTED_VALUE"""),"The B93R handgun was designed to fire a 9mm parabellum round from a 20 round clip. It is a relatively effective weapon against close ranged targets.") -> The B93R handgun was designed to fire a 9mm parabellum round from a 20 round clip. It is a relatively effective weapon against close ranged targets.
A35: =IFERROR(__xludf.DUMMYFUNCTION("""COMPUTED_VALUE"""),TRUE) -> TRUE | B35: =IFERROR(__xludf.DUMMYFUNCTION("""COMPUTED_VALUE"""),"") | C35: =IFERROR(__xludf.DUMMYFUNCTION("""COMPUTED_VALUE"""),101284.0) -> 101284 | D35: =IFERROR(__xludf.DUMMYFUNCTION("""COMPUTED_VALUE"""),"https://cdn.exe.in.th/marketing/WarzTH_LE/Item%20Dict/mre.png") -> https://cdn.exe.in.th/marketing/WarzTH_LE/Item%20Dict/mre.png | E35: =IFERROR(__xludf.DUMMYFUNCTION("""COMPUTED_VALUE"""),"Bag MRE") -> Bag MRE | F35: =IFERROR(__xludf.DUMMYFUNCTION("""COMPUTED_VALUE"""),1.0) -> 1 | G35: =IFERROR(__xludf.DUMMYFUNCTION("""COMPUTED_VALUE"""),"10 GC") -> 10 GC | H35: =IFERROR(__xludf.DUMMYFUNCTION("""COMPUTED_VALUE"""),"1,000 Dollars") -> 1,000 Dollars | I35: =IFERROR(__xludf.DUMMYFUNCTION("""COMPUTED_VALUE"""),"Consumable") -> Consumable | J35: =IFERROR(__xludf.DUMMYFUNCTION("""COMPUTED_VALUE"""),"Yes") -> Yes | L35: =IFERROR(__xludf.DUMMYFUNCTION("""COMPUTED_VALUE"""),"sftp://graphic@103.41.58.141/marketing/WarzTH_LE/Item%20Dict/mre.png") -> sftp://graphic@103.41.58.141/marketing/WarzTH_LE/Item%20Dict/mre.png | N35: =IFERROR(__xludf.DUMMYFUNCTION("""COMPUTED_VALUE"""),"Meals Ready-to-Eat. Extremely convenient! An MRE can be eaten cold, right out of the pouch but they always taste better hot. Each serving size substantially relieves hunger and thirst") -> Meals Ready-to-Eat. Extremely convenient! An MRE can be eaten cold, right out of the pouch but they always taste better hot. Each serving size substantially relieves hunger and thirst
A36: =IFERROR(__xludf.DUMMYFUNCTION("""COMPUTED_VALUE"""),TRUE) -> TRUE | B36: =IFERROR(__xludf.DUMMYFUNCTION("""COMPUTED_VALUE"""),"") | C36: =IFERROR(__xludf.DUMMYFUNCTION("""COMPUTED_VALUE"""),101283.0) -> 101283 | D36: =IFERROR(__xludf.DUMMYFUNCTION("""COMPUTED_VALUE"""),"https://cdn.exe.in.th/marketing/WarzTH_LE/Item%20Dict/bag_of_chips.png") -> https://cdn.exe.in.th/marketing/WarzTH_LE/Item%20Dict/bag_of_chips.png | E36: =IFERROR(__xludf.DUMMYFUNCTION("""COMPUTED_VALUE"""),"Bag of Chips") -> Bag of Chips | F36: =IFERROR(__xludf.DUMMYFUNCTION("""COMPUTED_VALUE"""),"-") -> - | G36: =IFERROR(__xludf.DUMMYFUNCTION("""COMPUTED_VALUE"""),"-") -> - | H36: =IFERROR(__xludf.DUMMYFUNCTION("""COMPUTED_VALUE"""),"-") -> - | I36: =IFERROR(__xludf.DUMMYFUNCTION("""COMPUTED_VALUE"""),"Consumable") -> Consumable | J36: =IFERROR(__xludf.DUMMYFUNCTION("""COMPUTED_VALUE"""),"Yes") -> Yes | L36: =IFERROR(__xludf.DUMMYFUNCTION("""COMPUTED_VALUE"""),"sftp://graphic@103.41.58.141/marketing/WarzTH_LE/Item%20Dict/bag_of_chips.png") -> sftp://graphic@103.41.58.141/marketing/WarzTH_LE/Item%20Dict/bag_of_chips.png | N36: =IFERROR(__xludf.DUMMYFUNCTION("""COMPUTED_VALUE"""),"A bag of potato chips. Relieves minor hunger. BBQ Flavor!") -> A bag of potato chips. Relieves minor hunger. BBQ Flavor!
A37: =IFERROR(__xludf.DUMMYFUNCTION("""COMPUTED_VALUE"""),TRUE) -> TRUE | B37: =IFERROR(__xludf.DUMMYFUNCTION("""COMPUTED_VALUE"""),"") | C37: =IFERROR(__xludf.DUMMYFUNCTION("""COMPUTED_VALUE"""),101510.0) -> 101510 | D37: =IFERROR(__xludf.DUMMYFUNCTION("""COMPUTED_VALUE"""),"https://cdn.exe.in.th/marketing/WarzTH_LE/Item%20Dict/bait_lv1.png") -> https://cdn.exe.in.th/marketing/WarzTH_LE/Item%20Dict/bait_lv1.png | E37: =IFERROR(__xludf.DUMMYFUNCTION("""COMPUTED_VALUE"""),"Bait") -> Bait | F37: =IFERROR(__xludf.DUMMYFUNCTION("""COMPUTED_VALUE"""),1.0) -> 1 | G37: =IFERROR(__xludf.DUMMYFUNCTION("""COMPUTED_VALUE"""),"-") -> - | H37: =IFERROR(__xludf.DUMMYFUNCTION("""COMPUTED_VALUE"""),"100 Dollars") -> 100 Dollars | I37: =IFERROR(__xludf.DUMMYFUNCTION("""COMPUTED_VALUE"""),"Consumable") -> Consumable | J37: =IFERROR(__xludf.DUMMYFUNCTION("""COMPUTED_VALUE"""),"Yes") -> Yes | L37: =IFERROR(__xludf.DUMMYFUNCTION("""COMPUTED_VALUE"""),"sftp://graphic@103.41.58.141/marketing/WarzTH_LE/Item%20Dict/bait_lv1.png") -> sftp://graphic@103.41.58.141/marketing/WarzTH_LE/Item%20Dict/bait_lv1.png
A38: =IFERROR(__xludf.DUMMYFUNCTION("""COMPUTED_VALUE"""),TRUE) -> TRUE | B38: =IFERROR(__xludf.DUMMYFUNCTION("""COMPUTED_VALUE"""),"") | C38: =IFERROR(__xludf.DUMMYFUNCTION("""COMPUTED_VALUE"""),101511.0) -> 101511 | D38: =IFERROR(__xludf.DUMMYFUNCTION("""COMPUTED_VALUE"""),"https://cdn.exe.in.th/marketing/WarzTH_LE/Item%20Dict/bait_lv2.png") -> https://cdn.exe.in.th/marketing/WarzTH_LE/Item%20Dict/bait_lv2.png | E38: =IFERROR(__xludf.DUMMYFUNCTION("""COMPUTED_VALUE"""),"Bait Premium") -> Bait Premium | F38: =IFERROR(__xludf.DUMMYFUNCTION("""COMPUTED_VALUE"""),1.0) -> 1 | G38: =IFERROR(__xludf.DUMMYFUNCTION("""COMPUTED_VALUE"""),"10 GC") -> 10 GC | H38: =IFERROR(__xludf.DUMMYFUNCTION("""COMPUTED_VALUE"""),"-") -> - | I38: =IFERROR(__xludf.DUMMYFUNCTION("""COMPUTED_VALUE"""),"Consumable") -> Consumable | J38: =IFERROR(__xludf.DUMMYFUNCTION("""COMPUTED_VALUE"""),"Yes") -> Yes | L38: =IFERROR(__xludf.DUMMYFUNCTION("""COMPUTED_VALUE"""),"sftp://graphic@103.41.58.141/marketing/WarzTH_LE/Item%20Dict/bait_lv2.png") -> sftp://graphic@103.41.58.141/marketing/WarzTH_LE/Item%20Dict/bait_lv2.png
A39: =IFERROR(__xludf.DUMMYFUNCTION("""COMPUTED_VALUE"""),TRUE) -> TRUE | B39: =IFERROR(__xludf.DUMMYFUNCTION("""COMPUTED_VALUE"""),"") | C39: =IFERROR(__xludf.DUMMYFUNCTION("""COMPUTED_VALUE"""),101261.0) -> 101261 | D39: =IFERROR(__xludf.DUMMYFUNCTION("""COMPUTED_VALUE"""),"https://cdn.exe.in.th/marketing/WarzTH_LE/Item%20Dict/bandages.png") -> https://cdn.exe.in.th/marketing/WarzTH_LE/Item%20Dict/bandages.png | E39: =IFERROR(__xludf.DUMMYFUNCTION("""COMPUTED_VALUE"""),"Bandages") -> Bandages | F39: =IFERROR(__xludf.DUMMYFUNCTION("""COMPUTED_VALUE"""),0.4) -> 0.4 | G39: =IFERROR(__xludf.DUMMYFUNCTION("""COMPUTED_VALUE"""),"-") -> - | H39: =IFERROR(__xludf.DUMMYFUNCTION("""COMPUTED_VALUE"""),"333 Dollars") -> 333 Dollars | I39: =IFERROR(__xludf.DUMMYFUNCTION("""COMPUTED_VALUE"""),"Consumable") -> Consumable | J39: =IFERROR(__xludf.DUMMYFUNCTION("""COMPUTED_VALUE"""),"Yes") -> Yes | L39: =IFERROR(__xludf.DUMMYFUNCTION("""COMPUTED_VALUE"""),"sftp://graphic@103.41.58.141/marketing/WarzTH_LE/Item%20Dict/bandages.png") -> sftp://graphic@103.41.58.141/marketing/WarzTH_LE/Item%20Dict/bandages.png | N39: =IFERROR(__xludf.DUMMYFUNCTION("""COMPUTED_VALUE"""),"Common bandages which heal minor wounds and stops excessive bleeding.") -> Common bandages which heal minor wounds and stops excessive bleeding.
A40: =IFERROR(__xludf.DUMMYFUNCTION("""COMPUTED_VALUE"""),TRUE) -> TRUE | B40: =IFERROR(__xludf.DUMMYFUNCTION("""COMPUTED_VALUE"""),"") | C40: =IFERROR(__xludf.DUMMYFUNCTION("""COMPUTED_VALUE"""),101262.0) -> 101262 | D40: =IFERROR(__xludf.DUMMYFUNCTION("""COMPUTED_VALUE"""),"https://cdn.exe.in.th/marketing/WarzTH_LE/Item%20Dict/bandages_dx.png") -> https://cdn.exe.in.th/marketing/WarzTH_LE/Item%20Dict/bandages_dx.png | E40: =IFERROR(__xludf.DUMMYFUNCTION("""COMPUTED_VALUE"""),"Bandages DX") -> Bandages DX | F40: =IFERROR(__xludf.DUMMYFUNCTION("""COMPUTED_VALUE"""),0.8) -> 0.8 | G40: =IFERROR(__xludf.DUMMYFUNCTION("""COMPUTED_VALUE"""),"8 GC 5 ea / 40 GC") -> 8 GC 5 ea / 40 GC | H40: =IFERROR(__xludf.DUMMYFUNCTION("""COMPUTED_VALUE"""),"800 Dollars 5 ea / 4,000 Dollars") -> 800 Dollars 5 ea / 4,000 Dollars | I40: =IFERROR(__xludf.DUMMYFUNCTION("""COMPUTED_VALUE"""),"Consumable") -> Consumable | J40: =IFERROR(__xludf.DUMMYFUNCTION("""COMPUTED_VALUE"""),"Yes") -> Yes | L40: =IFERROR(__xludf.DUMMYFUNCTION("""COMPUTED_VALUE"""),"sftp://graphic@103.41.58.141/marketing/WarzTH_LE/Item%20Dict/bandages_dx.png") -> sftp://graphic@103.41.58.141/marketing/WarzTH_LE/Item%20Dict/bandages_dx.png | N40: =IFERROR(__xludf.DUMMYFUNCTION("""COMPUTED_VALUE"""),"Medical bandages which heal moderate wounds and stops excessive bleeding.") -> Medical bandages which heal moderate wounds and stops excessive bleeding.
...

Sheet รายชื่อกิจกรรม
C1: ประกาศจากทีมงาน
E2: การจัดส่งของรางวัลทีมงานจะจัดส่งรางวัลต่าง ๆ ดังนี้
A3: ชื่อชีทที่มีสัญลักษณ์ 💛 = เก็บรายชื่อเสร็จแล้ว หรือ เป็น Master Code / Event All User Rewards | E3: • รางวัลที่รับบนหน้าเว็บไซต์ : ตัดรอบทุกวัน พุธ และจัดส่งให้รับรางวัลหน้าเว็บไซต์ได้ทุกวัน พุธ
E4: • รางวัลที่จัดส่งภายในเกม : จัดส่งทุกวันพุธ
E5: • รางวัลภายนอกเกม ประเภทพัสดุ : ตัดรอบทุกวัน xxxxxx เวลา 12.00 น. และจัดส่งพัสดุภายใน xxxxx
E6: • รางวัลภายนอกเกม ประเภท Voucher : ตัดรอบทุกวันที่ xxx และ xxx ของทุกเดือน และจัดส่งทาง sms ภายใน 15 และ 30 ของทุกเดือน
E7: กรณีที่วันดังกล่าวตรงกับวันหยุด ทีมงานจะส่งให้ในวันศุกร์ของสัปดาห์ที่ 2 และ 4 ของเดือนนั้นๆ แทน
C9: 💜 Purple | D9: 💜 Purple | E9: 💜 Purple | F9: 💜 Purple | G9: 💜 Purple | H9: 💜 Purple | I9: 💜 Purple | J9: 💜 Purple | K9: 💛 Yellow | L9: 💛 Yellow | M9: 💜 Purple
A10: No | B10: รายชื่อกิจกรรม | C10: วันเริ่มกิจกรรม | D10: วันจบกิจกรรม | E10: วันประกาศผล | F10: วันที่รับของรางวัล | G10: 🎁 วิธีการรับรางวัล | H10: 📌 Notion | I10: ระยะเวลายืนยันตัวตน | J10: ⚙️ อัปเดตสถานะ | K10: 👑 ใครรับงานเซต | L10: ⚙️ สถานะการทำงาน | M10: วันที่จัดส่ง / sms
A11: 1 | B11: แคปสิทธิ์ผู้รอดชีวิต | C11: 46153 | D11: 46170 | E11: 46183 | F11: 46183 | G11: 🌐หน้าเว็บไซต์ | H11: Notion | I11: - | J11: ⚙️ กำลังดำเนินการ
A12: 2 | B12: อาวุธคู่ใจ | C12: 46157 | D12: 46159 | E12: 46183 | F12: 46183 | G12: 🌐หน้าเว็บไซต์ | H12: [WarZ] จัดส่งของรางวัลกิจกรรมคอมมู "อาวุธคู่ใจ" | I12: - | J12: ⚙️ กำลังดำเนินการ
A13: 3 | B13: แอดไลน์ รับเสบียง | C13: 46165 | D13: 46167 | E13: 46183 | F13: 46183 | G13: 🌐หน้าเว็บไซต์ | H13: [WarZ] จัดส่งของรางวัลกิจกรรมคอมมู "แอดไลน์ รับเสบียง " | I13: - | J13: ⚙️ กำลังดำเนินการ
A14: 4 | B14: แจ้งบั๊ก รับของ | C14: 46170 | D14: 46173 | E14: 46183 | F14: 46183 | G14: 🌐หน้าเว็บไซต์ | H14: [WarZ] จัดส่งของรางวัลกิจกรรมคอมมู "แจ้งบัครับของ" | I14: - | J14: ⚙️ กำลังดำเนินการ
A15: 5 | B15: ปราบบอสพี่อู๋ | C15: 46178 | D15: 46181 | E15: 46183 | F15: 46183 | G15: 🌐หน้าเว็บไซต์ | H15: [WarZ] จัดส่งของรางวัลกิจกรรมคอมมู "ปราบบอสพี่อู๋ " | I15: - | J15: ⚙️ กำลังดำเนินการ
A16: 6 | B16: Bob Hunt | C16: 46170 | D16: 46173 | E16: 46183 | F16: 46183 | G16: HOF | H16: [WarZ] จัดส่งของรางวัลกิจกรรมคอมมู "Bob Hunt " | I16: - | J16: ⚙️ กำลังดำเนินการ
A17: 7 | B17: Bob Cap | C17: 46171 | D17: 46173 | E17: 46183 | F17: 46183 | G17: 🌐หน้าเว็บไซต์ | H17: [WarZ] จัดส่งของรางวัลกิจกรรมคอมมู "Bob Cap " | I17: - | J17: ⚙️ กำลังดำเนินการ
A18: 8 | B18: Fishing | C18: 46172 | D18: 46173 | E18: 46183 | F18: 46183 | G18: 🌐หน้าเว็บไซต์ | H18: [WarZ] จัดส่งของรางวัลกิจกรรมคอมมู "Fishing" | I18: - | J18: ⚙️ กำลังดำเนินการ
A19: 9 | B19: ภารกิจค้นหาเสบียงลับ | C19: 46176 | D19: 46178 | E19: 46190 | F19: 46190 | G19: 🌐หน้าเว็บไซต์ | H19: [WarZ] จัดส่งของรางวัลกิจกรรมคอมมู "ภารกิจค้นหาเสบียงลับ" | I19: - | J19: ⚙️ กำลังดำเนินการ

Sheet Template
A1: Template
A2: วันที่จัดส่ง | C2: รายละเอียดกิจกรรม และของรางวัล | D2: ผู้รับผิดชอบการจัดส่ง | E2: ตัดรอบบิลส่งของ | I2: ของรางวัลกิจกรรม
A3: สถานะการจัดส่ง | B3: ⚙️ กำลังดำเนินการ | C3: คลิกอ่านรายละเอียด | D3: ทีมสีเหลือง | E3: ทุกวันพุธ
I4: Bundle | J4: รางวัลสำหรับผู้เข้าร่วมทุกคน
A5: ระยะเวลากดรับของรางวัล (สำหรับสีเหลือง) | B5: เริ่ม | C5: 10 มิ.ย. 69 เวลา 12.00 น.
B6: สิ้นสุด | C6: 17 มิ.ย. 69 เวลา 23.59 น.
A8: NO. | B8: Reward | C8: Facebook | D8: UID | E8: วิธีการรับรางวัล | F8: สถานะการจัดส่ง
A9: 1 | B9: 🕹 Lucky Draw | E9: 🌐 เว็บไซต์ | F9: ✅ จัดส่งแล้ว | I9: ยังไม่เทส In-game | J9: Image | K9: Item ID | L9: Item EN | M9: Own Period | N9: Item Type | O9: Amount | P9: Total Price | Q9: Image URL
A10: 2 | I10: 1205 | J10: {=IFERROR(INDEX(Data!$A$4:$O1003, MATCH($L10, INDEX(Data!$A$4:$O1003, 0, MATCH("Item EN", Data!$A$3:$O$3, FALSE)), FALSE), MATCH("Image", Data!$A$3:$O$3, FALSE) ),"")} | K10: {=IFERROR(INDEX(Data!$A$4:$O1003, MATCH($L10, INDEX(Data!$A$4:$O1003, 0, MATCH("Item EN", Data!$A$3:$O$3, FALSE)), FALSE), MATCH("Item ID", Data!$A$3:$O$3, FALSE) ),"")} | N10: {=IFERROR(INDEX(Data!$A$4:$O1003, MATCH($L10, INDEX(Data!$A$4:$O1003, 0, MATCH("Item EN", Data!$A$3:$O$3, FALSE)), FALSE), MATCH("Item Type", Data!$A$3:$O$3, FALSE) ),"")} | P10: {=IF(O10="",,IFERROR(INDEX(Data!$A$4:$O1003, MATCH($L10, INDEX(Data!$A$4:$O1003, 0, MATCH("Item EN", Data!$A$3:$O$3, FALSE)), FALSE), MATCH("Price", Data!$A$3:$O$3, FALSE) ),"")*O10)} | Q10: {=IFERROR(INDEX(Data!$A$4:$O1003, MATCH($L10, INDEX(Data!$A$4:$O1003, 0, MATCH("Item EN", Data!$A$3:$O$3, FALSE)), FALSE), MATCH("Image URL", Data!$A$3:$O$3, FALSE) ),"")}
A11: 3 | I11: 1206 | J11: {=IFERROR(INDEX(Data!$A$4:$O1003, MATCH($L11, INDEX(Data!$A$4:$O1003, 0, MATCH("Item EN", Data!$A$3:$O$3, FALSE)), FALSE), MATCH("Image", Data!$A$3:$O$3, FALSE) ),"")} | K11: {=IFERROR(INDEX(Data!$A$4:$O1003, MATCH($L11, INDEX(Data!$A$4:$O1003, 0, MATCH("Item EN", Data!$A$3:$O$3, FALSE)), FALSE), MATCH("Item ID", Data!$A$3:$O$3, FALSE) ),"")} | N11: {=IFERROR(INDEX(Data!$A$4:$O1003, MATCH($L11, INDEX(Data!$A$4:$O1003, 0, MATCH("Item EN", Data!$A$3:$O$3, FALSE)), FALSE), MATCH("Item Type", Data!$A$3:$O$3, FALSE) ),"")} | P11: {=IF(O11="",,IFERROR(INDEX(Data!$A$4:$O1003, MATCH($L11, INDEX(Data!$A$4:$O1003, 0, MATCH("Item EN", Data!$A$3:$O$3, FALSE)), FALSE), MATCH("Price", Data!$A$3:$O$3, FALSE) ),"")*O11)} | Q11: {=IFERROR(INDEX(Data!$A$4:$O1003, MATCH($L11, INDEX(Data!$A$4:$O1003, 0, MATCH("Item EN", Data!$A$3:$O$3, FALSE)), FALSE), MATCH("Image URL", Data!$A$3:$O$3, FALSE) ),"")}
A12: 4 | I12: 1184 | J12: {=IFERROR(INDEX(Data!$A$4:$O1003, MATCH($L12, INDEX(Data!$A$4:$O1003, 0, MATCH("Item EN", Data!$A$3:$O$3, FALSE)), FALSE), MATCH("Image", Data!$A$3:$O$3, FALSE) ),"")} | K12: {=IFERROR(INDEX(Data!$A$4:$O1003, MATCH($L12, INDEX(Data!$A$4:$O1003, 0, MATCH("Item EN", Data!$A$3:$O$3, FALSE)), FALSE), MATCH("Item ID", Data!$A$3:$O$3, FALSE) ),"")} | N12: {=IFERROR(INDEX(Data!$A$4:$O1003, MATCH($L12, INDEX(Data!$A$4:$O1003, 0, MATCH("Item EN", Data!$A$3:$O$3, FALSE)), FALSE), MATCH("Item Type", Data!$A$3:$O$3, FALSE) ),"")} | P12: {=IF(O12="",,IFERROR(INDEX(Data!$A$4:$O1003, MATCH($L12, INDEX(Data!$A$4:$O1003, 0, MATCH("Item EN", Data!$A$3:$O$3, FALSE)), FALSE), MATCH("Price", Data!$A$3:$O$3, FALSE) ),"")*O12)} | Q12: {=IFERROR(INDEX(Data!$A$4:$O1003, MATCH($L12, INDEX(Data!$A$4:$O1003, 0, MATCH("Item EN", Data!$A$3:$O$3, FALSE)), FALSE), MATCH("Image URL", Data!$A$3:$O$3, FALSE) ),"")}
A13: 5 | I13: 1210 | J13: {=IFERROR(INDEX(Data!$A$4:$O1003, MATCH($L13, INDEX(Data!$A$4:$O1003, 0, MATCH("Item EN", Data!$A$3:$O$3, FALSE)), FALSE), MATCH("Image", Data!$A$3:$O$3, FALSE) ),"")} | K13: {=IFERROR(INDEX(Data!$A$4:$O1003, MATCH($L13, INDEX(Data!$A$4:$O1003, 0, MATCH("Item EN", Data!$A$3:$O$3, FALSE)), FALSE), MATCH("Item ID", Data!$A$3:$O$3, FALSE) ),"")} | N13: {=IFERROR(INDEX(Data!$A$4:$O1003, MATCH($L13, INDEX(Data!$A$4:$O1003, 0, MATCH("Item EN", Data!$A$3:$O$3, FALSE)), FALSE), MATCH("Item Type", Data!$A$3:$O$3, FALSE) ),"")} | P13: {=IF(O13="",,IFERROR(INDEX(Data!$A$4:$O1003, MATCH($L13, INDEX(Data!$A$4:$O1003, 0, MATCH("Item EN", Data!$A$3:$O$3, FALSE)), FALSE), MATCH("Price", Data!$A$3:$O$3, FALSE) ),"")*O13)} | Q13: {=IFERROR(INDEX(Data!$A$4:$O1003, MATCH($L13, INDEX(Data!$A$4:$O1003, 0, MATCH("Item EN", Data!$A$3:$O$3, FALSE)), FALSE), MATCH("Image URL", Data!$A$3:$O$3, FALSE) ),"")}
A14: 6 | I14: 1182 | J14: {=IFERROR(INDEX(Data!$A$4:$O1003, MATCH($L14, INDEX(Data!$A$4:$O1003, 0, MATCH("Item EN", Data!$A$3:$O$3, FALSE)), FALSE), MATCH("Image", Data!$A$3:$O$3, FALSE) ),"")} | K14: {=IFERROR(INDEX(Data!$A$4:$O1003, MATCH($L14, INDEX(Data!$A$4:$O1003, 0, MATCH("Item EN", Data!$A$3:$O$3, FALSE)), FALSE), MATCH("Item ID", Data!$A$3:$O$3, FALSE) ),"")} | N14: {=IFERROR(INDEX(Data!$A$4:$O1003, MATCH($L14, INDEX(Data!$A$4:$O1003, 0, MATCH("Item EN", Data!$A$3:$O$3, FALSE)), FALSE), MATCH("Item Type", Data!$A$3:$O$3, FALSE) ),"")} | P14: {=IF(O14="",,IFERROR(INDEX(Data!$A$4:$O1003, MATCH($L14, INDEX(Data!$A$4:$O1003, 0, MATCH("Item EN", Data!$A$3:$O$3, FALSE)), FALSE), MATCH("Price", Data!$A$3:$O$3, FALSE) ),"")*O14)} | Q14: {=IFERROR(INDEX(Data!$A$4:$O1003, MATCH($L14, INDEX(Data!$A$4:$O1003, 0, MATCH("Item EN", Data!$A$3:$O$3, FALSE)), FALSE), MATCH("Image URL", Data!$A$3:$O$3, FALSE) ),"")}
